Workbook
Name ConxBase: OFFSET(CONEXIONES!$C$10,0,0,MAX(1,COUNT(CONEXIONES!$A$10:$A$40)),1)
Name ConxDesc: OFFSET(CONEXIONES!$Y$10,0,0,MAX(1,COUNT(CONEXIONES!$A$10:$A$40)),1)
Name ConxDia: OFFSET(CONEXIONES!$B$10,0,0,MAX(1,COUNT(CONEXIONES!$A$10:$A$40)),1)
Name ConxMax: OFFSET(CONEXIONES!$D$10,0,0,MAX(1,COUNT(CONEXIONES!$A$10:$A$40)),1)
Name ConxNuevas: OFFSET(CONEXIONES!$E$10,0,0,MAX(1,COUNT(CONEXIONES!$A$10:$A$40)),1)
Name ConxPPK: OFFSET(CONEXIONES!$G$10,0,0,MAX(1,COUNT(CONEXIONES!$A$10:$A$40)),1)
Name ConxTotal: OFFSET(CONEXIONES!$H$10,0,0,MAX(1,COUNT(CONEXIONES!$A$10:$A$40)),1)
Name GrafCosto: OFFSET('VISTA MES'!$O$10,0,0,MAX(1,COUNT('VISTA MES'!$A$10:$A$39)),1)
Name GrafNaves: OFFSET('VISTA MES'!$E$10,0,0,MAX(1,COUNT('VISTA MES'!$A$10:$A$39)),1)
Name GrafVenta: OFFSET('VISTA MES'!$J$10,0,0,MAX(1,COUNT('VISTA MES'!$A$10:$A$39)),1)

Sheet RESUMEN
A1: REPORTE REEFER — COSTOS REALES 2026
A2: Costos reales PPK y SITRANS en CLP. Combustible total mensual en USD, sin distribución por nave.
A3: ="ÚLTIMO MES CON COSTOS REALES: "&UPPER(INDEX($A$9:$A$20,COUNT($B$9:$B$20)))&" 2026" -> ÚLTIMO MES CON COSTOS REALES: SEPTIEMBRE 2026
A4: REEFERS | C4: PPK ÚNICOS | E4: DÍAS-PPK | G4: PPK + SITRANS CLP | I4: COMBUSTIBLE USD | K4: ESTADO EDP | M4: COSTO TOTAL CLP/REEFER
A5: =INDEX($B$9:$B$20,COUNT($B$9:$B$20)) -> 1151 | C5: =INDEX($C$9:$C$20,COUNT($B$9:$B$20)) -> 9 | E5: =INDEX($D$9:$D$20,COUNT($B$9:$B$20)) -> 90 | G5: =INDEX($G$9:$G$20,COUNT($B$9:$B$20)) -> 39938519 | I5: =INDEX($J$9:$J$20,COUNT($B$9:$B$20)) -> 79706.23 | K5: =INDEX($L$9:$L$20,COUNT($B$9:$B$20)) -> Disponible incompleto | M5: =INDEX($O$9:$O$20,COUNT($B$9:$B$20)) -> 97369.815
A8: Mes | B8: Reefers | C8: PPK únicos | D8: Días-PPK | E8: SITRANS CLP | F8: PPK CLP | G8: Total CLP | H8: CLP/reefer | I8: Combustible L | J8: Combustible USD | K8: Estadía prom. días | L8: Estado EDP | M8: TC CLP/USD | N8: Costo total CLP | O8: Costo total CLP/reefer | P8: % SITRANS | Q8: % PPK | R8: % Combustible | S8: Var. reefers % | T8: Var. costo total % | U8: US$ combustible/reefer-día | V8: Venta real USD | W8: Costo real USD | X8: Margen real USD | Y8: Margen real %
A9: Enero | B9: =IF(ACTUALIZAR!B7="","",ACTUALIZAR!B7) -> 88 | C9: =IF(PPK!B7="","",PPK!B7) -> 2 | D9: =IF(PPK!C7="","",PPK!C7) -> 31 | E9: =IF(ACTUALIZAR!C7="","",ACTUALIZAR!C7) -> 12918273 | F9: =IF(PPK!F7="","",PPK!F7) -> 9514784 | G9: =IF(AND(E9="",F9=""),"",SUM(E9:F9)) -> 22433057 | H9: =IFERROR(N9/B9,"") -> 348759.94 | I9: =IF(ACTUALIZAR!E7="","",ACTUALIZAR!E7) -> 13228.63 | J9: =IF(ACTUALIZAR!F7="","",ACTUALIZAR!F7) -> 9124.66 | K9: =IFERROR(SUMPRODUCT((NAVES!$A$7:$A$200=A9)*NAVES!$F$7:$F$200*NAVES!$G$7:$G$200)/SUMIF(NAVES!$A$7:$A$200,A9,NAVES!$F$7:$F$200),"") -> 6.1794074 | L9: =ACTUALIZAR!G7 -> Disponible | M9: =IF(ACTUALIZAR!I7="","",ACTUALIZAR!I7) -> 905 | N9: =IF(OR(G9="",J9="",M9=""),"",G9+J9*M9) -> 30690874 | O9: =IFERROR(N9/B9,"") -> 348759.94 | P9: =IFERROR(E9/N9,"") -> 0.42091577 | Q9: =IFERROR(F9/N9,"") -> 0.31001997 | R9: =IFERROR((J9*M9)/N9,"") -> 0.26906426 | S9: ="" | T9: ="" | U9: =IFERROR((J9/B9)/K9,"") -> 16.779816 | V9: 71088.33 | W9: =IFERROR(N9/M9,"") -> 33912.568 | X9: =IFERROR(V9-W9,"") -> 37175.762 | Y9: =IFERROR(X9/V9,"") -> 0.52295168
A10: Febrero | B10: =IF(ACTUALIZAR!B8="","",ACTUALIZAR!B8) -> 54 | C10: =IF(PPK!B8="","",PPK!B8) -> 2 | D10: =IF(PPK!C8="","",PPK!C8) -> 34 | E10: =IF(ACTUALIZAR!C8="","",ACTUALIZAR!C8) -> 12918273 | F10: =IF(PPK!F8="","",PPK!F8) -> 10336991 | G10: =IF(AND(E10="",F10=""),"",SUM(E10:F10)) -> 23255264 | H10: =IFERROR(N10/B10,"") -> 595963.52 | I10: =IF(ACTUALIZAR!E8="","",ACTUALIZAR!E8) -> 13525.31 | J10: =IF(ACTUALIZAR!F8="","",ACTUALIZAR!F8) -> 9863.83 | K10: =IFERROR(SUMPRODUCT((NAVES!$A$7:$A$200=A10)*NAVES!$F$7:$F$200*NAVES!$G$7:$G$200)/SUMIF(NAVES!$A$7:$A$200,A10,NAVES!$F$7:$F$200),"") -> 14.934472 | L10: =ACTUALIZAR!G8 -> Disponible incompleto | M10: =IF(ACTUALIZAR!I8="","",ACTUALIZAR!I8) -> 905 | N10: =IF(OR(G10="",J10="",M10=""),"",G10+J10*M10) -> 32182030 | O10: =IFERROR(N10/B10,"") -> 595963.52 | P10: =IFERROR(E10/N10,"") -> 0.40141262 | Q10: =IFERROR(F10/N10,"") -> 0.32120382 | R10: =IFERROR((J10*M10)/N10,"") -> 0.27738356 | S10: =IFERROR(B10/B9-1,"") -> -0.38636364 | T10: =IFERROR(N10/N9-1,"") -> 0.048586294 | U10: =IFERROR((J10/B10)/K10,"") -> 12.230999 | V10: 53916.57 | W10: =IFERROR(N10/M10,"") -> 35560.254 | X10: =IFERROR(V10-W10,"") -> 18356.316 | Y10: =IFERROR(X10/V10,"") -> 0.34045778
A11: Marzo | B11: =IF(ACTUALIZAR!B9="","",ACTUALIZAR!B9) -> 72 | C11: =IF(PPK!B9="","",PPK!B9) -> 2 | D11: =IF(PPK!C9="","",PPK!C9) -> 31 | E11: =IF(ACTUALIZAR!C9="","",ACTUALIZAR!C9) -> 12918273 | F11: =IF(PPK!F9="","",PPK!F9) -> 9514784 | G11: =IF(AND(E11="",F11=""),"",SUM(E11:F11)) -> 22433057 | H11: =IFERROR(N11/B11,"") -> 423642.67 | I11: =IF(ACTUALIZAR!E9="","",ACTUALIZAR!E9) -> 7812.79 | J11: =IF(ACTUALIZAR!F9="","",ACTUALIZAR!F9) -> 8916.26 | K11: =IFERROR(SUMPRODUCT((NAVES!$A$7:$A$200=A11)*NAVES!$F$7:$F$200*NAVES!$G$7:$G$200)/SUMIF(NAVES!$A$7:$A$200,A11,NAVES!$F$7:$F$200),"") -> 8.1315297 | L11: =ACTUALIZAR!G9 -> Disponible | M11: =IF(ACTUALIZAR!I9="","",ACTUALIZAR!I9) -> 905 | N11: =IF(OR(G11="",J11="",M11=""),"",G11+J11*M11) -> 30502272 | O11: =IFERROR(N11/B11,"") -> 423642.67 | P11: =IFERROR(E11/N11,"") -> 0.42351838 | Q11: =IFERROR(F11/N11,"") -> 0.31193689 | R11: =IFERROR((J11*M11)/N11,"") -> 0.26454473 | S11: =IFERROR(B11/B10-1,"") -> 0.33333333 | T11: =IFERROR(N11/N10-1,"") -> -0.052195522 | U11: =IFERROR((J11/B11)/K11,"") -> 15.229231 | V11: 71738.1 | W11: =IFERROR(N11/M11,"") -> 33704.168 | X11: =IFERROR(V11-W11,"") -> 38033.932 | Y11: =IFERROR(X11/V11,"") -> 0.53017757
A12: Abril | B12: =IF(ACTUALIZAR!B10="","",ACTUALIZAR!B10) -> 23 | C12: =IF(PPK!B10="","",PPK!B10) -> 1 | D12: =IF(PPK!C10="","",PPK!C10) -> 30 | E12: =IF(ACTUALIZAR!C10="","",ACTUALIZAR!C10) -> 12918273 | F12: =IF(PPK!F10="","",PPK!F10) -> 9240715 | G12: =IF(AND(E12="",F12=""),"",SUM(E12:F12)) -> 22158988 | H12: =IFERROR(N12/B12,"") -> 1004353.6 | I12: =IF(ACTUALIZAR!E10="","",ACTUALIZAR!E10) -> 804.81 | J12: =IF(ACTUALIZAR!F10="","",ACTUALIZAR!F10) -> 1039.94 | K12: =IFERROR(SUMPRODUCT((NAVES!$A$7:$A$200=A12)*NAVES!$F$7:$F$200*NAVES!$G$7:$G$200)/SUMIF(NAVES!$A$7:$A$200,A12,NAVES!$F$7:$F$200),"") -> 6.2434179 | L12: =ACTUALIZAR!G10 -> Disponible | M12: =IF(ACTUALIZAR!I10="","",ACTUALIZAR!I10) -> 905 | N12: =IF(OR(G12="",J12="",M12=""),"",G12+J12*M12) -> 23100134 | O12: =IFERROR(N12/B12,"") -> 1004353.6 | P12: =IFERROR(E12/N12,"") -> 0.55922936 | Q12: =IFERROR(F12/N12,"") -> 0.40002864 | R12: =IFERROR((J12*M12)/N12,"") -> 0.040742002 | S12: =IFERROR(B12/B11-1,"") -> -0.68055556 | T12: =IFERROR(N12/N11-1,"") -> -0.24267499 | U12: =IFERROR((J12/B12)/K12,"") -> 7.241992 | V12: 19736 | W12: =IFERROR(N12/M12,"") -> 25525.01 | X12: =IFERROR(V12-W12,"") -> -5789.0096 | Y12: =IFERROR(X12/V12,"") -> -0.29332234
A13: Mayo | B13: =IF(ACTUALIZAR!B11="","",ACTUALIZAR!B11) -> 47 | C13: =IF(PPK!B11="","",PPK!B11) -> 2 | D13: =IF(PPK!C11="","",PPK!C11) -> 31 | E13: =IF(ACTUALIZAR!C11="","",ACTUALIZAR!C11) -> 12918273 | F13: =IF(PPK!F11="","",PPK!F11) -> 9514784 | G13: =IF(AND(E13="",F13=""),"",SUM(E13:F13)) -> 22433057 | H13: =IFERROR(N13/B13,"") -> 700396.32 | I13: =IF(ACTUALIZAR!E11="","",ACTUALIZAR!E11) -> 8444.64 | J13: =IF(ACTUALIZAR!F11="","",ACTUALIZAR!F11) -> 11586.265 | K13: =IFERROR(SUMPRODUCT((NAVES!$A$7:$A$200=A13)*NAVES!$F$7:$F$200*NAVES!$G$7:$G$200)/SUMIF(NAVES!$A$7:$A$200,A13,NAVES!$F$7:$F$200),"") -> 6.4853086 | L13: =ACTUALIZAR!G11 -> Disponible incompleto | M13: =IF(ACTUALIZAR!I11="","",ACTUALIZAR!I11) -> 905 | N13: =IF(OR(G13="",J13="",M13=""),"",G13+J13*M13) -> 32918627 | O13: =IFERROR(N13/B13,"") -> 700396.32 | P13: =IFERROR(E13/N13,"") -> 0.39243049 | Q13: =IFERROR(F13/N13,"") -> 0.28903952 | R13: =IFERROR((J13*M13)/N13,"") -> 0.31852999 | S13: =IFERROR(B13/B12-1,"") -> 1.0434783 | T13: =IFERROR(N13/N12-1,"") -> 0.42504053 | U13: =IFERROR((J13/B13)/K13,"") -> 38.011495 | V13: 41288 | W13: =IFERROR(N13/M13,"") -> 36374.173 | X13: =IFERROR(V13-W13,"") -> 4913.8267 | Y13: =IFERROR(X13/V13,"") -> 0.11901343
A14: Junio | B14: =IF(ACTUALIZAR!B12="","",ACTUALIZAR!B12) -> 213 | C14: =IF(PPK!B12="","",PPK!B12) -> 3 | D14: =IF(PPK!C12="","",PPK!C12) -> 32 | E14: =IF(ACTUALIZAR!C12="","",ACTUALIZAR!C12) -> 12918273 | F14: =IF(PPK!F12="","",PPK!F12) -> 9788853 | G14: =IF(AND(E14="",F14=""),"",SUM(E14:F14)) -> 22707126 | H14: =IFERROR(N14/B14,"") -> 137879.03 | I14: =IF(ACTUALIZAR!E12="","",ACTUALIZAR!E12) -> 7391.7 | J14: =IF(ACTUALIZAR!F12="","",ACTUALIZAR!F12) -> 7360.34 | K14: =IFERROR(SUMPRODUCT((NAVES!$A$7:$A$200=A14)*NAVES!$F$7:$F$200*NAVES!$G$7:$G$200)/SUMIF(NAVES!$A$7:$A$200,A14,NAVES!$F$7:$F$200),"") -> 1.7942195 | L14: =ACTUALIZAR!G12 -> Disponible | M14: =IF(ACTUALIZAR!I12="","",ACTUALIZAR!I12) -> 905 | N14: =IF(OR(G14="",J14="",M14=""),"",G14+J14*M14) -> 29368234 | O14: =IFERROR(N14/B14,"") -> 137879.03 | P14: =IFERROR(E14/N14,"") -> 0.43987232 | Q14: =IFERROR(F14/N14,"") -> 0.33331433 | R14: =IFERROR((J14*M14)/N14,"") -> 0.22681336 | S14: =IFERROR(B14/B13-1,"") -> 3.5319149 | T14: =IFERROR(N14/N13-1,"") -> -0.10785362 | U14: =IFERROR((J14/B14)/K14,"") -> 19.259398 | V14: 54592 | W14: =IFERROR(N14/M14,"") -> 32451.087 | X14: =IFERROR(V14-W14,"") -> 22140.913 | Y14: =IFERROR(X14/V14,"") -> 0.40557065
A15: Julio | B15: =IF(ACTUALIZAR!B13="","",ACTUALIZAR!B13) -> 547 | C15: =IF(PPK!B13="","",PPK!B13) -> 4 | D15: =IF(PPK!C13="","",PPK!C13) -> 35 | E15: =IF(ACTUALIZAR!C13="","",ACTUALIZAR!C13) -> 13585968 | F15: =IF(PPK!F13="","",PPK!F13) -> 10611062 | G15: =IF(AND(E15="",F15=""),"",SUM(E15:F15)) -> 24197030 | H15: =IFERROR(N15/B15,"") -> 80687.65 | I15: =IF(ACTUALIZAR!E13="","",ACTUALIZAR!E13) -> 19860.92 | J15: =IF(ACTUALIZAR!F13="","",ACTUALIZAR!F13) -> 22032.17 | K15: =IFERROR(SUMPRODUCT((NAVES!$A$7:$A$200=A15)*NAVES!$F$7:$F$200*NAVES!$G$7:$G$200)/SUMIF(NAVES!$A$7:$A$200,A15,NAVES!$F$7:$F$200),"") -> 2.3124476 | L15: =ACTUALIZAR!G13 -> Disponible incompleto | M15: =IF(ACTUALIZAR!I13="","",ACTUALIZAR!I13) -> 905 | N15: =IF(OR(G15="",J15="",M15=""),"",G15+J15*M15) -> 44136144 | O15: =IFERROR(N15/B15,"") -> 80687.65 | P15: =IFERROR(E15/N15,"") -> 0.30781956 | Q15: =IFERROR(F15/N15,"") -> 0.24041661 | R15: =IFERROR((J15*M15)/N15,"") -> 0.45176384 | S15: =IFERROR(B15/B14-1,"") -> 1.5680751 | T15: =IFERROR(N15/N14-1,"") -> 0.50285321 | U15: =IFERROR((J15/B15)/K15,"") -> 17.417991 | V15: 198088 | W15: =IFERROR(N15/M15,"") -> 48769.22 | X15: =IFERROR(V15-W15,"") -> 149318.78 | Y15: =IFERROR(X15/V15,"") -> 0.75380023
A16: Agosto | B16: =IF(ACTUALIZAR!B14="","",ACTUALIZAR!B14) -> 751 | C16: =IF(PPK!B14="","",PPK!B14) -> 9 | D16: =IF(PPK!C14="","",PPK!C14) -> 74 | E16: =IF(ACTUALIZAR!C14="","",ACTUALIZAR!C14) -> 13919815 | F16: =IF(PPK!F14="","",PPK!F14) -> 21299751 | G16: =IF(AND(E16="",F16=""),"",SUM(E16:F16)) -> 35219566 | H16: =IFERROR(N16/B16,"") -> 104647.34 | I16: =IF(ACTUALIZAR!E14="","",ACTUALIZAR!E14) -> 39428.23 | J16: =IF(ACTUALIZAR!F14="","",ACTUALIZAR!F14) -> 47923.3 | K16: =IFERROR(SUMPRODUCT((NAVES!$A$7:$A$200=A16)*NAVES!$F$7:$F$200*NAVES!$G$7:$G$200)/SUMIF(NAVES!$A$7:$A$200,A16,NAVES!$F$7:$F$200),"") -> 2.9878828 | L16: =ACTUALIZAR!G14 -> Disponible | M16: =IF(ACTUALIZAR!I14="","",ACTUALIZAR!I14) -> 905 | N16: =IF(OR(G16="",J16="",M16=""),"",G16+J16*M16) -> 78590153 | O16: =IFERROR(N16/B16,"") -> 104647.34 | P16: =IFERROR(E16/N16,"") -> 0.17711907 | Q16: =IFERROR(F16/N16,"") -> 0.27102315 | R16: =IFERROR((J16*M16)/N16,"") -> 0.55185777 | S16: =IFERROR(B16/B15-1,"") -> 0.37294333 | T16: =IFERROR(N16/N15-1,"") -> 0.78063023 | U16: =IFERROR((J16/B16)/K16,"") -> 21.357146 | V16: 305408 | W16: =IFERROR(N16/M16,"") -> 86839.948 | X16: =IFERROR(V16-W16,"") -> 218568.05 | Y16: =IFERROR(X16/V16,"") -> 0.71565922
A17: Septiembre | B17: =IF(ACTUALIZAR!B15="","",ACTUALIZAR!B15) -> 1151 | C17: =IF(PPK!B15="","",PPK!B15) -> 9 | D17: =IF(PPK!C15="","",PPK!C15) -> 90 | E17: =IF(ACTUALIZAR!C15="","",ACTUALIZAR!C15) -> 14253664 | F17: =IF(PPK!F15="","",PPK!F15) -> 25684855 | G17: =IF(AND(E17="",F17=""),"",SUM(E17:F17)) -> 39938519 | H17: =IFERROR(N17/B17,"") -> 97369.815 | I17: =IF(ACTUALIZAR!E15="","",ACTUALIZAR!E15) -> 58941.29 | J17: =IF(ACTUALIZAR!F15="","",ACTUALIZAR!F15) -> 79706.23 | K17: =IFERROR(SUMPRODUCT((NAVES!$A$7:$A$200=A17)*NAVES!$F$7:$F$200*NAVES!$G$7:$G$200)/SUMIF(NAVES!$A$7:$A$200,A17,NAVES!$F$7:$F$200),"") -> 2.8327074 | L17: =ACTUALIZAR!G15 -> Disponible incompleto | M17: =IF(ACTUALIZAR!I15="","",ACTUALIZAR!I15) -> 905 | N17: =IF(OR(G17="",J17="",M17=""),"",G17+J17*M17) -> 1.1207266e+08 | O17: =IFERROR(N17/B17,"") -> 97369.815 | P17: =IFERROR(E17/N17,"") -> 0.12718235 | Q17: =IFERROR(F17/N17,"") -> 0.22918039 | R17: =IFERROR((J17*M17)/N17,"") -> 0.64363726 | S17: =IFERROR(B17/B16-1,"") -> 0.53262317 | T17: =IFERROR(N17/N16-1,"") -> 0.42603944 | U17: =IFERROR((J17/B17)/K17,"") -> 24.446417 | V17: 630824 | W17: =IFERROR(N17/M17,"") -> 123837.19 | X17: =IFERROR(V17-W17,"") -> 506986.81 | Y17: =IFERROR(X17/V17,"") -> 0.80368979
A18: Octubre | B18: =IF(ACTUALIZAR!B16="","",ACTUALIZAR!B16) | C18: =IF(PPK!B16="","",PPK!B16) | D18: =IF(PPK!C16="","",PPK!C16) | E18: =IF(ACTUALIZAR!C16="","",ACTUALIZAR!C16) | F18: =IF(PPK!F16="","",PPK!F16) | G18: =IF(AND(E18="",F18=""),"",SUM(E18:F18)) | H18: =IFERROR(N18/B18,"") | I18: =IF(ACTUALIZAR!E16="","",ACTUALIZAR!E16) | J18: =IF(ACTUALIZAR!F16="","",ACTUALIZAR!F16) | K18: =IFERROR(SUMPRODUCT((NAVES!$A$7:$A$200=A18)*NAVES!$F$7:$F$200*NAVES!$G$7:$G$200)/SUMIF(NAVES!$A$7:$A$200,A18,NAVES!$F$7:$F$200),"") | L18: =ACTUALIZAR!G16 -> Pendiente | M18: =IF(ACTUALIZAR!I16="","",ACTUALIZAR!I16) | N18: =IF(OR(G18="",J18="",M18=""),"",G18+J18*M18) | O18: =IFERROR(N18/B18,"") | P18: =IFERROR(E18/N18,"") | Q18: =IFERROR(F18/N18,"") | R18: =IFERROR((J18*M18)/N18,"") | S18: =IFERROR(B18/B17-1,"") | T18: =IFERROR(N18/N17-1,"") | U18: =IFERROR((J18/B18)/K18,"") | W18: =IFERROR(N18/M18,"") | X18: =IFERROR(V18-W18,"") | Y18: =IFERROR(X18/V18,"")
A19: Noviembre | B19: =IF(ACTUALIZAR!B17="","",ACTUALIZAR!B17) | C19: =IF(PPK!B17="","",PPK!B17) | D19: =IF(PPK!C17="","",PPK!C17) | E19: =IF(ACTUALIZAR!C17="","",ACTUALIZAR!C17) | F19: =IF(PPK!F17="","",PPK!F17) | G19: =IF(AND(E19="",F19=""),"",SUM(E19:F19)) | H19: =IFERROR(N19/B19,"") | I19: =IF(ACTUALIZAR!E17="","",ACTUALIZAR!E17) | J19: =IF(ACTUALIZAR!F17="","",ACTUALIZAR!F17) | K19: =IFERROR(SUMPRODUCT((NAVES!$A$7:$A$200=A19)*NAVES!$F$7:$F$200*NAVES!$G$7:$G$200)/SUMIF(NAVES!$A$7:$A$200,A19,NAVES!$F$7:$F$200),"") | L19: =ACTUALIZAR!G17 -> Pendiente | M19: =IF(ACTUALIZAR!I17="","",ACTUALIZAR!I17) | N19: =IF(OR(G19="",J19="",M19=""),"",G19+J19*M19) | O19: =IFERROR(N19/B19,"") | P19: =IFERROR(E19/N19,"") | Q19: =IFERROR(F19/N19,"") | R19: =IFERROR((J19*M19)/N19,"") | S19: =IFERROR(B19/B18-1,"") | T19: =IFERROR(N19/N18-1,"") | U19: =IFERROR((J19/B19)/K19,"") | W19: =IFERROR(N19/M19,"") | X19: =IFERROR(V19-W19,"") | Y19: =IFERROR(X19/V19,"")
A20: Diciembre | B20: =IF(ACTUALIZAR!B18="","",ACTUALIZAR!B18) | C20: =IF(PPK!B18="","",PPK!B18) | D20: =IF(PPK!C18="","",PPK!C18) | E20: =IF(ACTUALIZAR!C18="","",ACTUALIZAR!C18) | F20: =IF(PPK!F18="","",PPK!F18) | G20: =IF(AND(E20="",F20=""),"",SUM(E20:F20)) | H20: =IFERROR(N20/B20,"") | I20: =IF(ACTUALIZAR!E18="","",ACTUALIZAR!E18) | J20: =IF(ACTUALIZAR!F18="","",ACTUALIZAR!F18) | K20: =IFERROR(SUMPRODUCT((NAVES!$A$7:$A$200=A20)*NAVES!$F$7:$F$200*NAVES!$G$7:$G$200)/SUMIF(NAVES!$A$7:$A$200,A20,NAVES!$F$7:$F$200),"") | L20: =ACTUALIZAR!G18 -> Pendiente | M20: =IF(ACTUALIZAR!I18="","",ACTUALIZAR!I18) | N20: =IF(OR(G20="",J20="",M20=""),"",G20+J20*M20) | O20: =IFERROR(N20/B20,"") | P20: =IFERROR(E20/N20,"") | Q20: =IFERROR(F20/N20,"") | R20: =IFERROR((J20*M20)/N20,"") | S20: =IFERROR(B20/B19-1,"") | T20: =IFERROR(N20/N19-1,"") | U20: =IFERROR((J20/B20)/K20,"") | W20: =IFERROR(N20/M20,"") | X20: =IFERROR(V20-W20,"") | Y20: =IFERROR(X20/V20,"")
A21: TOTAL ENE–SEP | B21: =SUM(B9:B20) -> 2946 | D21: =SUM(D9:D20) -> 388 | E21: =SUM(E9:E20) -> 1.1926909e+08 | F21: =SUM(F9:F20) -> 115506579 | G21: =SUM(G9:G20) -> 2.3477566e+08 | H21: =IFERROR(G21/B21,"") -> 79693.029 | I21: =SUM(I9:I20) -> 169438.32 | J21: =SUM(J9:J20) -> 197553 | K21: =IFERROR(SUMPRODUCT(NAVES!$F$7:$F$200,NAVES!$G$7:$G$200)/SUM(NAVES!$F$7:$F$200),"") -> 3.2074956 | L21: Ene–Sep con EDP | N21: =IF(COUNT(N9:N20)=0,"",SUM(N9:N20)) -> 4.1356112e+08 | O21: =IFERROR(N21/B21,"") -> 140380.56 | P21: =IFERROR(E21/N21,"") -> 0.2883953 | Q21: =IFERROR(F21/N21,"") -> 0.27929748 | R21: =IFERROR((SUM(J9:J20)*905)/N21,"") -> 0.43230722 | V21: =IF(COUNT(V9:V20)=0,"",SUM(V9:V20)) -> 1446679 | W21: =IF(COUNT(W9:W20)=0,"",SUM(W9:W20)) -> 456973.62 | X21: =IFERROR(V21-W21,"") -> 989705.38 | Y21: =IFERROR(X21/V21,"") -> 0.68412231

Sheet VISTA MES
A1: VISTA POR MES — NAVES, VENTA Y MARGEN REEFER 2026
A2: Elige el mes en la celda amarilla. Reefers = OC SITRANS. Venta por nave: Naves por Servicios (Servicio Reefer). SITRANS y PPK se asignan por reefers; el combustible del mes se prorratea por reefers.
A4: MES | B4: Septiembre | D4: TC CLP/USD | E4: =IFERROR(INDEX(RESUMEN!$M$9:$M$20,MATCH($B$4,RESUMEN!$A$9:$A$20,0)),"") -> 905 | G4: Combustible mes USD | I4: =IFERROR(INDEX(RESUMEN!$J$9:$J$20,MATCH($B$4,RESUMEN!$A$9:$A$20,0)),"") -> 79706.23 | K4: Estado EDP | L4: =IFERROR(INDEX(ACTUALIZAR!$G$7:$G$18,MATCH($B$4,ACTUALIZAR!$A$7:$A$18,0)),"") -> Disponible incompleto | N4: Control venta vs RESUMEN | P4: =IFERROR(J40-INDEX(RESUMEN!$V$9:$V$20,MATCH($B$4,RESUMEN!$A$9:$A$20,0)),"") -> 0
A6: NAVES | C6: REEFERS OC | E6: VENTA USD | G6: COSTO USD | I6: MARGEN USD | K6: MARGEN % | M6: VENTA/REEFER | O6: COSTO/REEFER | Q6: ESTADÍA PROM.
A7: =IFERROR(MAX(NAVES!$P$7:$P$200),"") -> 18 | C7: =IFERROR(F40,"") -> 1151 | E7: =IFERROR(J40,"") -> 630824 | G7: =IFERROR(O40,"") -> 123837.19 | I7: =IFERROR(P40,"") -> 506986.81 | K7: =IFERROR(Q40,"") -> 0.80368979 | M7: =IFERROR(R40,"") -> 548.06603 | O7: =IFERROR(S40,"") -> 107.59096 | Q7: =IFERROR(H40,"") -> 2.8327074
A9: # | B9: CI | C9: Correlativo | D9: Línea | E9: Nave | F9: Reefers OC | G9: EDP válidos | H9: Estadía prom. días | I9: Estado EDP | J9: Venta USD | K9: SITRANS CLP | L9: PPK CLP | M9: Combustible CLP | N9: Costo total CLP | O9: Costo total USD | P9: Margen USD | Q9: Margen % | R9: Venta/reefer USD | S9: Costo/reefer USD
A10: =IF($U10="","",1) -> 1 | B10: =IF($U10="","",INDEX(NAVES!$B$7:$B$200,$U10)) -> 8426 | C10: =IF($U10="","",IF(INDEX(NAVES!$M$7:$M$200,$U10)="","",INDEX(NAVES!$M$7:$M$200,$U10))) -> 2026-182 | D10: =IF($U10="","",INDEX(NAVES!$C$7:$C$200,$U10)) -> Por confirmar | E10: =IF($U10="","",INDEX(NAVES!$D$7:$D$200,$U10)) -> ALIOTH 1 | F10: =IF($U10="","",INDEX(NAVES!$E$7:$E$200,$U10)) -> 1 | G10: =IF($U10="","",IF(INDEX(NAVES!$F$7:$F$200,$U10)="","",INDEX(NAVES!$F$7:$F$200,$U10))) -> 1 | H10: =IF($U10="","",IF(INDEX(NAVES!$G$7:$G$200,$U10)="","",INDEX(NAVES!$G$7:$G$200,$U10))) -> 6.04 | I10: =IF($U10="","",INDEX(NAVES!$H$7:$H$200,$U10)) -> Disponible | J10: =IF($U10="","",N(INDEX(NAVES!$N$7:$N$200,$U10))) -> 656 | K10: =IF($U10="","",N(INDEX(NAVES!$I$7:$I$200,$U10))) -> 12383.722 | L10: =IF($U10="","",N(INDEX(NAVES!$J$7:$J$200,$U10))) -> 22315.252 | M10: =IF($U10="","",IFERROR(F10/SUMIF(NAVES!$A$7:$A$200,$B$4,NAVES!$E$7:$E$200)*$I$4*$E$4,0)) -> 62670.841 | N10: =IF($U10="","",K10+L10+M10) -> 97369.815 | O10: =IF($U10="","",IFERROR(N10/$E$4,"")) -> 107.59096 | P10: =IF($U10="","",IFERROR(J10-O10,"")) -> 548.40904 | Q10: =IF($U10="","",IFERROR(P10/J10,"")) -> 0.8359894 | R10: =IF($U10="","",IFERROR(J10/F10,"")) -> 656 | S10: =IF($U10="","",IFERROR(O10/F10,"")) -> 107.59096 | U10: =IFERROR(MATCH(1,NAVES!$P$7:$P$200,0),"") -> 76
A11: =IF($U11="","",2) -> 2 | B11: =IF($U11="","",INDEX(NAVES!$B$7:$B$200,$U11)) -> 8427 | C11: =IF($U11="","",IF(INDEX(NAVES!$M$7:$M$200,$U11)="","",INDEX(NAVES!$M$7:$M$200,$U11))) -> 2026-181 | D11: =IF($U11="","",INDEX(NAVES!$C$7:$C$200,$U11)) -> MSC | E11: =IF($U11="","",INDEX(NAVES!$D$7:$D$200,$U11)) -> MSC ABUJA VI | F11: =IF($U11="","",INDEX(NAVES!$E$7:$E$200,$U11)) -> 4 | G11: =IF($U11="","",IF(INDEX(NAVES!$F$7:$F$200,$U11)="","",INDEX(NAVES!$F$7:$F$200,$U11))) -> 4 | H11: =IF($U11="","",IF(INDEX(NAVES!$G$7:$G$200,$U11)="","",INDEX(NAVES!$G$7:$G$200,$U11))) -> 5.44 | I11: =IF($U11="","",INDEX(NAVES!$H$7:$H$200,$U11)) -> Disponible | J11: =IF($U11="","",N(INDEX(NAVES!$N$7:$N$200,$U11))) -> 3200 | K11: =IF($U11="","",N(INDEX(NAVES!$I$7:$I$200,$U11))) -> 49534.887 | L11: =IF($U11="","",N(INDEX(NAVES!$J$7:$J$200,$U11))) -> 89261.008 | M11: =IF($U11="","",IFERROR(F11/SUMIF(NAVES!$A$7:$A$200,$B$4,NAVES!$E$7:$E$200)*$I$4*$E$4,0)) -> 250683.36 | N11: =IF($U11="","",K11+L11+M11) -> 389479.26 | O11: =IF($U11="","",IFERROR(N11/$E$4,"")) -> 430.36382 | P11: =IF($U11="","",IFERROR(J11-O11,"")) -> 2769.6362 | Q11: =IF($U11="","",IFERROR(P11/J11,"")) -> 0.86551131 | R11: =IF($U11="","",IFERROR(J11/F11,"")) -> 800 | S11: =IF($U11="","",IFERROR(O11/F11,"")) -> 107.59096 | U11: =IFERROR(MATCH(2,NAVES!$P$7:$P$200,0),"") -> 77
A12: =IF($U12="","",3) -> 3 | B12: =IF($U12="","",INDEX(NAVES!$B$7:$B$200,$U12)) -> 8428 | C12: =IF($U12="","",IF(INDEX(NAVES!$M$7:$M$200,$U12)="","",INDEX(NAVES!$M$7:$M$200,$U12))) -> 2026-185 | D12: =IF($U12="","",INDEX(NAVES!$C$7:$C$200,$U12)) -> Por confirmar | E12: =IF($U12="","",INDEX(NAVES!$D$7:$D$200,$U12)) -> CAPE BRUNO 1 | F12: =IF($U12="","",INDEX(NAVES!$E$7:$E$200,$U12)) -> 2 | G12: =IF($U12="","",IF(INDEX(NAVES!$F$7:$F$200,$U12)="","",INDEX(NAVES!$F$7:$F$200,$U12))) -> 2 | H12: =IF($U12="","",IF(INDEX(NAVES!$G$7:$G$200,$U12)="","",INDEX(NAVES!$G$7:$G$200,$U12))) -> 4.6 | I12: =IF($U12="","",INDEX(NAVES!$H$7:$H$200,$U12)) -> Disponible | J12: =IF($U12="","",N(INDEX(NAVES!$N$7:$N$200,$U12))) -> 512 | K12: =IF($U12="","",N(INDEX(NAVES!$I$7:$I$200,$U12))) -> 24767.444 | L12: =IF($U12="","",N(INDEX(NAVES!$J$7:$J$200,$U12))) -> 44630.504 | M12: =IF($U12="","",IFERROR(F12/SUMIF(NAVES!$A$7:$A$200,$B$4,NAVES!$E$7:$E$200)*$I$4*$E$4,0)) -> 125341.68 | N12: =IF($U12="","",K12+L12+M12) -> 194739.63 | O12: =IF($U12="","",IFERROR(N12/$E$4,"")) -> 215.18191 | P12: =IF($U12="","",IFERROR(J12-O12,"")) -> 296.81809 | Q12: =IF($U12="","",IFERROR(P12/J12,"")) -> 0.57972283 | R12: =IF($U12="","",IFERROR(J12/F12,"")) -> 256 | S12: =IF($U12="","",IFERROR(O12/F12,"")) -> 107.59096 | U12: =IFERROR(MATCH(3,NAVES!$P$7:$P$200,0),"") -> 78
A13: =IF($U13="","",4) -> 4 | B13: =IF($U13="","",INDEX(NAVES!$B$7:$B$200,$U13)) -> 8429 | C13: =IF($U13="","",IF(INDEX(NAVES!$M$7:$M$200,$U13)="","",INDEX(NAVES!$M$7:$M$200,$U13))) | D13: =IF($U13="","",INDEX(NAVES!$C$7:$C$200,$U13)) -> Por confirmar | E13: =IF($U13="","",INDEX(NAVES!$D$7:$D$200,$U13)) -> LITTLE ATHINA | F13: =IF($U13="","",INDEX(NAVES!$E$7:$E$200,$U13)) -> 1 | G13: =IF($U13="","",IF(INDEX(NAVES!$F$7:$F$200,$U13)="","",INDEX(NAVES!$F$7:$F$200,$U13))) -> 0 | H13: =IF($U13="","",IF(INDEX(NAVES!$G$7:$G$200,$U13)="","",INDEX(NAVES!$G$7:$G$200,$U13))) | I13: =IF($U13="","",INDEX(NAVES!$H$7:$H$200,$U13)) -> Parcial | J13: =IF($U13="","",N(INDEX(NAVES!$N$7:$N$200,$U13))) -> 0 | K13: =IF($U13="","",N(INDEX(NAVES!$I$7:$I$200,$U13))) -> 12383.722 | L13: =IF($U13="","",N(INDEX(NAVES!$J$7:$J$200,$U13))) -> 22315.252 | M13: =IF($U13="","",IFERROR(F13/SUMIF(NAVES!$A$7:$A$200,$B$4,NAVES!$E$7:$E$200)*$I$4*$E$4,0)) -> 62670.841 | N13: =IF($U13="","",K13+L13+M13) -> 97369.815 | O13: =IF($U13="","",IFERROR(N13/$E$4,"")) -> 107.59096 | P13: =IF($U13="","",IFERROR(J13-O13,"")) -> -107.59096 | Q13: =IF($U13="","",IFERROR(P13/J13,"")) | R13: =IF($U13="","",IFERROR(J13/F13,"")) -> 0 | S13: =IF($U13="","",IFERROR(O13/F13,"")) -> 107.59096 | U13: =IFERROR(MATCH(4,NAVES!$P$7:$P$200,0),"") -> 79
A14: =IF($U14="","",5) -> 5 | B14: =IF($U14="","",INDEX(NAVES!$B$7:$B$200,$U14)) -> 8430 | C14: =IF($U14="","",IF(INDEX(NAVES!$M$7:$M$200,$U14)="","",INDEX(NAVES!$M$7:$M$200,$U14))) -> 2026-186 | D14: =IF($U14="","",INDEX(NAVES!$C$7:$C$200,$U14)) -> MAERSK | E14: =IF($U14="","",INDEX(NAVES!$D$7:$D$200,$U14)) -> POLAR CHILE | F14: =IF($U14="","",INDEX(NAVES!$E$7:$E$200,$U14)) -> 268 | G14: =IF($U14="","",IF(INDEX(NAVES!$F$7:$F$200,$U14)="","",INDEX(NAVES!$F$7:$F$200,$U14))) -> 267 | H14: =IF($U14="","",IF(INDEX(NAVES!$G$7:$G$200,$U14)="","",INDEX(NAVES!$G$7:$G$200,$U14))) -> 2.69 | I14: =IF($U14="","",INDEX(NAVES!$H$7:$H$200,$U14)) -> Parcial | J14: =IF($U14="","",N(INDEX(NAVES!$N$7:$N$200,$U14))) -> 145144 | K14: =IF($U14="","",N(INDEX(NAVES!$I$7:$I$200,$U14))) -> 3318837.5 | L14: =IF($U14="","",N(INDEX(NAVES!$J$7:$J$200,$U14))) -> 5980487.5 | M14: =IF($U14="","",IFERROR(F14/SUMIF(NAVES!$A$7:$A$200,$B$4,NAVES!$E$7:$E$200)*$I$4*$E$4,0)) -> 16795785 | N14: =IF($U14="","",K14+L14+M14) -> 26095110 | O14: =IF($U14="","",IFERROR(N14/$E$4,"")) -> 28834.376 | P14: =IF($U14="","",IFERROR(J14-O14,"")) -> 116309.62 | Q14: =IF($U14="","",IFERROR(P14/J14,"")) -> 0.80133952 | R14: =IF($U14="","",IFERROR(J14/F14,"")) -> 541.58209 | S14: =IF($U14="","",IFERROR(O14/F14,"")) -> 107.59096 | U14: =IFERROR(MATCH(5,NAVES!$P$7:$P$200,0),"") -> 80
A15: =IF($U15="","",6) -> 6 | B15: =IF($U15="","",INDEX(NAVES!$B$7:$B$200,$U15)) -> 8431 | C15: =IF($U15="","",IF(INDEX(NAVES!$M$7:$M$200,$U15)="","",INDEX(NAVES!$M$7:$M$200,$U15))) -> 2026-177 | D15: =IF($U15="","",INDEX(NAVES!$C$7:$C$200,$U15)) -> HAPAG LLOYD / ON | E15: =IF($U15="","",INDEX(NAVES!$D$7:$D$200,$U15)) -> HUMBOLDT EXPRESS | F15: =IF($U15="","",INDEX(NAVES!$E$7:$E$200,$U15)) -> 17 | G15: =IF($U15="","",IF(INDEX(NAVES!$F$7:$F$200,$U15)="","",INDEX(NAVES!$F$7:$F$200,$U15))) -> 17 | H15: =IF($U15="","",IF(INDEX(NAVES!$G$7:$G$200,$U15)="","",INDEX(NAVES!$G$7:$G$200,$U15))) -> 8.62 | I15: =IF($U15="","",INDEX(NAVES!$H$7:$H$200,$U15)) -> Disponible | J15: =IF($U15="","",N(INDEX(NAVES!$N$7:$N$200,$U15))) -> 16440 | K15: =IF($U15="","",N(INDEX(NAVES!$I$7:$I$200,$U15))) -> 210523.27 | L15: =IF($U15="","",N(INDEX(NAVES!$J$7:$J$200,$U15))) -> 379359.28 | M15: =IF($U15="","",IFERROR(F15/SUMIF(NAVES!$A$7:$A$200,$B$4,NAVES!$E$7:$E$200)*$I$4*$E$4,0)) -> 1065404.3 | N15: =IF($U15="","",K15+L15+M15) -> 1655286.9 | O15: =IF($U15="","",IFERROR(N15/$E$4,"")) -> 1829.0462 | P15: =IF($U15="","",IFERROR(J15-O15,"")) -> 14610.954 | Q15: =IF($U15="","",IFERROR(P15/J15,"")) -> 0.88874415 | R15: =IF($U15="","",IFERROR(J15/F15,"")) -> 967.05882 | S15: =IF($U15="","",IFERROR(O15/F15,"")) -> 107.59096 | U15: =IFERROR(MATCH(6,NAVES!$P$7:$P$200,0),"") -> 81
A16: =IF($U16="","",7) -> 7 | B16: =IF($U16="","",INDEX(NAVES!$B$7:$B$200,$U16)) -> 8432 | C16: =IF($U16="","",IF(INDEX(NAVES!$M$7:$M$200,$U16)="","",INDEX(NAVES!$M$7:$M$200,$U16))) -> 2026-192 | D16: =IF($U16="","",INDEX(NAVES!$C$7:$C$200,$U16)) -> SEABOARD | E16: =IF($U16="","",INDEX(NAVES!$D$7:$D$200,$U16)) -> MOLLY SCHULTE 1 | F16: =IF($U16="","",INDEX(NAVES!$E$7:$E$200,$U16)) -> 9 | G16: =IF($U16="","",IF(INDEX(NAVES!$F$7:$F$200,$U16)="","",INDEX(NAVES!$F$7:$F$200,$U16))) -> 9 | H16: =IF($U16="","",IF(INDEX(NAVES!$G$7:$G$200,$U16)="","",INDEX(NAVES!$G$7:$G$200,$U16))) -> 9.29 | I16: =IF($U16="","",INDEX(NAVES!$H$7:$H$200,$U16)) -> Disponible | J16: =IF($U16="","",N(INDEX(NAVES!$N$7:$N$200,$U16))) -> 7560 | K16: =IF($U16="","",N(INDEX(NAVES!$I$7:$I$200,$U16))) -> 111453.5 | L16: =IF($U16="","",N(INDEX(NAVES!$J$7:$J$200,$U16))) -> 200837.27 | M16: =IF($U16="","",IFERROR(F16/SUMIF(NAVES!$A$7:$A$200,$B$4,NAVES!$E$7:$E$200)*$I$4*$E$4,0)) -> 564037.57 | N16: =IF($U16="","",K16+L16+M16) -> 876328.33 | O16: =IF($U16="","",IFERROR(N16/$E$4,"")) -> 968.3186 | P16: =IF($U16="","",IFERROR(J16-O16,"")) -> 6591.6814 | Q16: =IF($U16="","",IFERROR(P16/J16,"")) -> 0.87191553 | R16: =IF($U16="","",IFERROR(J16/F16,"")) -> 840 | S16: =IF($U16="","",IFERROR(O16/F16,"")) -> 107.59096 | U16: =IFERROR(MATCH(7,NAVES!$P$7:$P$200,0),"") -> 82
A17: =IF($U17="","",8) -> 8 | B17: =IF($U17="","",INDEX(NAVES!$B$7:$B$200,$U17)) -> 8433 | C17: =IF($U17="","",IF(INDEX(NAVES!$M$7:$M$200,$U17)="","",INDEX(NAVES!$M$7:$M$200,$U17))) -> 2026-188 | D17: =IF($U17="","",INDEX(NAVES!$C$7:$C$200,$U17)) -> MSC | E17: =IF($U17="","",INDEX(NAVES!$D$7:$D$200,$U17)) -> MSC YOKOHAMA | F17: =IF($U17="","",INDEX(NAVES!$E$7:$E$200,$U17)) -> 12 | G17: =IF($U17="","",IF(INDEX(NAVES!$F$7:$F$200,$U17)="","",INDEX(NAVES!$F$7:$F$200,$U17))) -> 12 | H17: =IF($U17="","",IF(INDEX(NAVES!$G$7:$G$200,$U17)="","",INDEX(NAVES!$G$7:$G$200,$U17))) -> 6.06 | I17: =IF($U17="","",INDEX(NAVES!$H$7:$H$200,$U17)) -> Disponible | J17: =IF($U17="","",N(INDEX(NAVES!$N$7:$N$200,$U17))) -> 12000 | K17: =IF($U17="","",N(INDEX(NAVES!$I$7:$I$200,$U17))) -> 148604.66 | L17: =IF($U17="","",N(INDEX(NAVES!$J$7:$J$200,$U17))) -> 267783.02 | M17: =IF($U17="","",IFERROR(F17/SUMIF(NAVES!$A$7:$A$200,$B$4,NAVES!$E$7:$E$200)*$I$4*$E$4,0)) -> 752050.09 | N17: =IF($U17="","",K17+L17+M17) -> 1168437.8 | O17: =IF($U17="","",IFERROR(N17/$E$4,"")) -> 1291.0915 | P17: =IF($U17="","",IFERROR(J17-O17,"")) -> 10708.909 | Q17: =IF($U17="","",IFERROR(P17/J17,"")) -> 0.89240904 | R17: =IF($U17="","",IFERROR(J17/F17,"")) -> 1000 | S17: =IF($U17="","",IFERROR(O17/F17,"")) -> 107.59096 | U17: =IFERROR(MATCH(8,NAVES!$P$7:$P$200,0),"") -> 83
A18: =IF($U18="","",9) -> 9 | B18: =IF($U18="","",INDEX(NAVES!$B$7:$B$200,$U18)) -> 8434 | C18: =IF($U18="","",IF(INDEX(NAVES!$M$7:$M$200,$U18)="","",INDEX(NAVES!$M$7:$M$200,$U18))) -> 2026-187 | D18: =IF($U18="","",INDEX(NAVES!$C$7:$C$200,$U18)) -> MAERSK | E18: =IF($U18="","",INDEX(NAVES!$D$7:$D$200,$U18)) -> POLAR ARGENTINA | F18: =IF($U18="","",INDEX(NAVES!$E$7:$E$200,$U18)) -> 210 | G18: =IF($U18="","",IF(INDEX(NAVES!$F$7:$F$200,$U18)="","",INDEX(NAVES!$F$7:$F$200,$U18))) -> 210 | H18: =IF($U18="","",IF(INDEX(NAVES!$G$7:$G$200,$U18)="","",INDEX(NAVES!$G$7:$G$200,$U18))) -> 2.91 | I18: =IF($U18="","",INDEX(NAVES!$H$7:$H$200,$U18)) -> Disponible | J18: =IF($U18="","",N(INDEX(NAVES!$N$7:$N$200,$U18))) -> 147896 | K18: =IF($U18="","",N(INDEX(NAVES!$I$7:$I$200,$U18))) -> 2600581.6 | L18: =IF($U18="","",N(INDEX(NAVES!$J$7:$J$200,$U18))) -> 4686202.9 | M18: =IF($U18="","",IFERROR(F18/SUMIF(NAVES!$A$7:$A$200,$B$4,NAVES!$E$7:$E$200)*$I$4*$E$4,0)) -> 13160877 | N18: =IF($U18="","",K18+L18+M18) -> 20447661 | O18: =IF($U18="","",IFERROR(N18/$E$4,"")) -> 22594.101 | P18: =IF($U18="","",IFERROR(J18-O18,"")) -> 125301.9 | Q18: =IF($U18="","",IFERROR(P18/J18,"")) -> 0.84722981 | R18: =IF($U18="","",IFERROR(J18/F18,"")) -> 704.26667 | S18: =IF($U18="","",IFERROR(O18/F18,"")) -> 107.59096 | U18: =IFERROR(MATCH(9,NAVES!$P$7:$P$200,0),"") -> 84
A19: =IF($U19="","",10) -> 10 | B19: =IF($U19="","",INDEX(NAVES!$B$7:$B$200,$U19)) -> 8436 | C19: =IF($U19="","",IF(INDEX(NAVES!$M$7:$M$200,$U19)="","",INDEX(NAVES!$M$7:$M$200,$U19))) -> 2026-196 | D19: =IF($U19="","",INDEX(NAVES!$C$7:$C$200,$U19)) -> Por confirmar | E19: =IF($U19="","",INDEX(NAVES!$D$7:$D$200,$U19)) -> ALIOTH 2 | F19: =IF($U19="","",INDEX(NAVES!$E$7:$E$200,$U19)) -> 1 | G19: =IF($U19="","",IF(INDEX(NAVES!$F$7:$F$200,$U19)="","",INDEX(NAVES!$F$7:$F$200,$U19))) -> 1 | H19: =IF($U19="","",IF(INDEX(NAVES!$G$7:$G$200,$U19)="","",INDEX(NAVES!$G$7:$G$200,$U19))) -> 6.52 | I19: =IF($U19="","",INDEX(NAVES!$H$7:$H$200,$U19)) -> Disponible | J19: =IF($U19="","",N(INDEX(NAVES!$N$7:$N$200,$U19))) -> 616 | K19: =IF($U19="","",N(INDEX(NAVES!$I$7:$I$200,$U19))) -> 12383.722 | L19: =IF($U19="","",N(INDEX(NAVES!$J$7:$J$200,$U19))) -> 22315.252 | M19: =IF($U19="","",IFERROR(F19/SUMIF(NAVES!$A$7:$A$200,$B$4,NAVES!$E$7:$E$200)*$I$4*$E$4,0)) -> 62670.841 | N19: =IF($U19="","",K19+L19+M19) -> 97369.815 | O19: =IF($U19="","",IFERROR(N19/$E$4,"")) -> 107.59096 | P19: =IF($U19="","",IFERROR(J19-O19,"")) -> 508.40904 | Q19: =IF($U19="","",IFERROR(P19/J19,"")) -> 0.82533936 | R19: =IF($U19="","",IFERROR(J19/F19,"")) -> 616 | S19: =IF($U19="","",IFERROR(O19/F19,"")) -> 107.59096 | U19: =IFERROR(MATCH(10,NAVES!$P$7:$P$200,0),"") -> 85
A20: =IF($U20="","",11) -> 11 | B20: =IF($U20="","",INDEX(NAVES!$B$7:$B$200,$U20)) -> 8437 | C20: =IF($U20="","",IF(INDEX(NAVES!$M$7:$M$200,$U20)="","",INDEX(NAVES!$M$7:$M$200,$U20))) | D20: =IF($U20="","",INDEX(NAVES!$C$7:$C$200,$U20)) -> Por confirmar | E20: =IF($U20="","",INDEX(NAVES!$D$7:$D$200,$U20)) -> CAPE BRUNO 2 | F20: =IF($U20="","",INDEX(NAVES!$E$7:$E$200,$U20)) -> 1 | G20: =IF($U20="","",IF(INDEX(NAVES!$F$7:$F$200,$U20)="","",INDEX(NAVES!$F$7:$F$200,$U20))) -> 1 | H20: =IF($U20="","",IF(INDEX(NAVES!$G$7:$G$200,$U20)="","",INDEX(NAVES!$G$7:$G$200,$U20))) -> 2.34 | I20: =IF($U20="","",INDEX(NAVES!$H$7:$H$200,$U20)) -> Disponible | J20: =IF($U20="","",N(INDEX(NAVES!$N$7:$N$200,$U20))) -> 0 | K20: =IF($U20="","",N(INDEX(NAVES!$I$7:$I$200,$U20))) -> 12383.722 | L20: =IF($U20="","",N(INDEX(NAVES!$J$7:$J$200,$U20))) -> 22315.252 | M20: =IF($U20="","",IFERROR(F20/SUMIF(NAVES!$A$7:$A$200,$B$4,NAVES!$E$7:$E$200)*$I$4*$E$4,0)) -> 62670.841 | N20: =IF($U20="","",K20+L20+M20) -> 97369.815 | O20: =IF($U20="","",IFERROR(N20/$E$4,"")) -> 107.59096 | P20: =IF($U20="","",IFERROR(J20-O20,"")) -> -107.59096 | Q20: =IF($U20="","",IFERROR(P20/J20,"")) | R20: =IF($U20="","",IFERROR(J20/F20,"")) -> 0 | S20: =IF($U20="","",IFERROR(O20/F20,"")) -> 107.59096 | U20: =IFERROR(MATCH(11,NAVES!$P$7:$P$200,0),"") -> 86
A21: =IF($U21="","",12) -> 12 | B21: =IF($U21="","",INDEX(NAVES!$B$7:$B$200,$U21)) -> 8438 | C21: =IF($U21="","",IF(INDEX(NAVES!$M$7:$M$200,$U21)="","",INDEX(NAVES!$M$7:$M$200,$U21))) -> 2026-190 | D21: =IF($U21="","",INDEX(NAVES!$C$7:$C$200,$U21)) -> HAPAG LLOYD / ON | E21: =IF($U21="","",INDEX(NAVES!$D$7:$D$200,$U21)) -> ONE SINCERITY | F21: =IF($U21="","",INDEX(NAVES!$E$7:$E$200,$U21)) -> 37 | G21: =IF($U21="","",IF(INDEX(NAVES!$F$7:$F$200,$U21)="","",INDEX(NAVES!$F$7:$F$200,$U21))) -> 37 | H21: =IF($U21="","",IF(INDEX(NAVES!$G$7:$G$200,$U21)="","",INDEX(NAVES!$G$7:$G$200,$U21))) -> 7.17 | I21: =IF($U21="","",INDEX(NAVES!$H$7:$H$200,$U21)) -> Disponible | J21: =IF($U21="","",N(INDEX(NAVES!$N$7:$N$200,$U21))) -> 27608 | K21: =IF($U21="","",N(INDEX(NAVES!$I$7:$I$200,$U21))) -> 458197.71 | L21: =IF($U21="","",N(INDEX(NAVES!$J$7:$J$200,$U21))) -> 825664.32 | M21: =IF($U21="","",IFERROR(F21/SUMIF(NAVES!$A$7:$A$200,$B$4,NAVES!$E$7:$E$200)*$I$4*$E$4,0)) -> 2318821.1 | N21: =IF($U21="","",K21+L21+M21) -> 3602683.2 | O21: =IF($U21="","",IFERROR(N21/$E$4,"")) -> 3980.8654 | P21: =IF($U21="","",IFERROR(J21-O21,"")) -> 23627.135 | Q21: =IF($U21="","",IFERROR(P21/J21,"")) -> 0.85580754 | R21: =IF($U21="","",IFERROR(J21/F21,"")) -> 746.16216 | S21: =IF($U21="","",IFERROR(O21/F21,"")) -> 107.59096 | U21: =IFERROR(MATCH(12,NAVES!$P$7:$P$200,0),"") -> 87
A22: =IF($U22="","",13) -> 13 | B22: =IF($U22="","",INDEX(NAVES!$B$7:$B$200,$U22)) -> 8439 | C22: =IF($U22="","",IF(INDEX(NAVES!$M$7:$M$200,$U22)="","",INDEX(NAVES!$M$7:$M$200,$U22))) -> 2026-200 | D22: =IF($U22="","",INDEX(NAVES!$C$7:$C$200,$U22)) -> MAERSK | E22: =IF($U22="","",INDEX(NAVES!$D$7:$D$200,$U22)) -> POLAR PERU | F22: =IF($U22="","",INDEX(NAVES!$E$7:$E$200,$U22)) -> 166 | G22: =IF($U22="","",IF(INDEX(NAVES!$F$7:$F$200,$U22)="","",INDEX(NAVES!$F$7:$F$200,$U22))) -> 166 | H22: =IF($U22="","",IF(INDEX(NAVES!$G$7:$G$200,$U22)="","",INDEX(NAVES!$G$7:$G$200,$U22))) -> 2 | I22: =IF($U22="","",INDEX(NAVES!$H$7:$H$200,$U22)) -> Disponible | J22: =IF($U22="","",N(INDEX(NAVES!$N$7:$N$200,$U22))) -> 69784 | K22: =IF($U22="","",N(INDEX(NAVES!$I$7:$I$200,$U22))) -> 2055697.8 | L22: =IF($U22="","",N(INDEX(NAVES!$J$7:$J$200,$U22))) -> 3704331.8 | M22: =IF($U22="","",IFERROR(F22/SUMIF(NAVES!$A$7:$A$200,$B$4,NAVES!$E$7:$E$200)*$I$4*$E$4,0)) -> 10403360 | N22: =IF($U22="","",K22+L22+M22) -> 16163389 | O22: =IF($U22="","",IFERROR(N22/$E$4,"")) -> 17860.099 | P22: =IF($U22="","",IFERROR(J22-O22,"")) -> 51923.901 | Q22: =IF($U22="","",IFERROR(P22/J22,"")) -> 0.74406599 | R22: =IF($U22="","",IFERROR(J22/F22,"")) -> 420.38554 | S22: =IF($U22="","",IFERROR(O22/F22,"")) -> 107.59096 | U22: =IFERROR(MATCH(13,NAVES!$P$7:$P$200,0),"") -> 88
A23: =IF($U23="","",14) -> 14 | B23: =IF($U23="","",INDEX(NAVES!$B$7:$B$200,$U23)) -> 8440 | C23: =IF($U23="","",IF(INDEX(NAVES!$M$7:$M$200,$U23)="","",INDEX(NAVES!$M$7:$M$200,$U23))) -> 2026-199 | D23: =IF($U23="","",INDEX(NAVES!$C$7:$C$200,$U23)) -> MSC | E23: =IF($U23="","",INDEX(NAVES!$D$7:$D$200,$U23)) -> MSC FLORIANA VI | F23: =IF($U23="","",INDEX(NAVES!$E$7:$E$200,$U23)) -> 2 | G23: =IF($U23="","",IF(INDEX(NAVES!$F$7:$F$200,$U23)="","",INDEX(NAVES!$F$7:$F$200,$U23))) -> 2 | H23: =IF($U23="","",IF(INDEX(NAVES!$G$7:$G$200,$U23)="","",INDEX(NAVES!$G$7:$G$200,$U23))) -> 12.09 | I23: =IF($U23="","",INDEX(NAVES!$H$7:$H$200,$U23)) -> Disponible | J23: =IF($U23="","",N(INDEX(NAVES!$N$7:$N$200,$U23))) -> 4704 | K23: =IF($U23="","",N(INDEX(NAVES!$I$7:$I$200,$U23))) -> 24767.444 | L23: =IF($U23="","",N(INDEX(NAVES!$J$7:$J$200,$U23))) -> 44630.504 | M23: =IF($U23="","",IFERROR(F23/SUMIF(NAVES!$A$7:$A$200,$B$4,NAVES!$E$7:$E$200)*$I$4*$E$4,0)) -> 125341.68 | N23: =IF($U23="","",K23+L23+M23) -> 194739.63 | O23: =IF($U23="","",IFERROR(N23/$E$4,"")) -> 215.18191 | P23: =IF($U23="","",IFERROR(J23-O23,"")) -> 4488.8181 | Q23: =IF($U23="","",IFERROR(P23/J23,"")) -> 0.95425555 | R23: =IF($U23="","",IFERROR(J23/F23,"")) -> 2352 | S23: =IF($U23="","",IFERROR(O23/F23,"")) -> 107.59096 | U23: =IFERROR(MATCH(14,NAVES!$P$7:$P$200,0),"") -> 89
A24: =IF($U24="","",15) -> 15 | B24: =IF($U24="","",INDEX(NAVES!$B$7:$B$200,$U24)) -> 8442 | C24: =IF($U24="","",IF(INDEX(NAVES!$M$7:$M$200,$U24)="","",INDEX(NAVES!$M$7:$M$200,$U24))) -> 2026-191 | D24: =IF($U24="","",INDEX(NAVES!$C$7:$C$200,$U24)) -> HAPAG LLOYD / ON | E24: =IF($U24="","",INDEX(NAVES!$D$7:$D$200,$U24)) -> ONE SAPHIRE | F24: =IF($U24="","",INDEX(NAVES!$E$7:$E$200,$U24)) -> 29 | G24: =IF($U24="","",IF(INDEX(NAVES!$F$7:$F$200,$U24)="","",INDEX(NAVES!$F$7:$F$200,$U24))) -> 29 | H24: =IF($U24="","",IF(INDEX(NAVES!$G$7:$G$200,$U24)="","",INDEX(NAVES!$G$7:$G$200,$U24))) -> 5.51 | I24: =IF($U24="","",INDEX(NAVES!$H$7:$H$200,$U24)) -> Disponible | J24: =IF($U24="","",N(INDEX(NAVES!$N$7:$N$200,$U24))) -> 26856 | K24: =IF($U24="","",N(INDEX(NAVES!$I$7:$I$200,$U24))) -> 359127.93 | L24: =IF($U24="","",N(INDEX(NAVES!$J$7:$J$200,$U24))) -> 647142.31 | M24: =IF($U24="","",IFERROR(F24/SUMIF(NAVES!$A$7:$A$200,$B$4,NAVES!$E$7:$E$200)*$I$4*$E$4,0)) -> 1817454.4 | N24: =IF($U24="","",K24+L24+M24) -> 2823724.6 | O24: =IF($U24="","",IFERROR(N24/$E$4,"")) -> 3120.1377 | P24: =IF($U24="","",IFERROR(J24-O24,"")) -> 23735.862 | Q24: =IF($U24="","",IFERROR(P24/J24,"")) -> 0.88381972 | R24: =IF($U24="","",IFERROR(J24/F24,"")) -> 926.06897 | S24: =IF($U24="","",IFERROR(O24/F24,"")) -> 107.59096 | U24: =IFERROR(MATCH(15,NAVES!$P$7:$P$200,0),"") -> 90
A25: =IF($U25="","",16) -> 16 | B25: =IF($U25="","",INDEX(NAVES!$B$7:$B$200,$U25)) -> 8443 | C25: =IF($U25="","",IF(INDEX(NAVES!$M$7:$M$200,$U25)="","",INDEX(NAVES!$M$7:$M$200,$U25))) -> 2026-204 | D25: =IF($U25="","",INDEX(NAVES!$C$7:$C$200,$U25)) -> MAERSK | E25: =IF($U25="","",INDEX(NAVES!$D$7:$D$200,$U25)) -> POLAR COLOMBIA | F25: =IF($U25="","",INDEX(NAVES!$E$7:$E$200,$U25)) -> 387 | G25: =IF($U25="","",IF(INDEX(NAVES!$F$7:$F$200,$U25)="","",INDEX(NAVES!$F$7:$F$200,$U25))) -> 385 | H25: =IF($U25="","",IF(INDEX(NAVES!$G$7:$G$200,$U25)="","",INDEX(NAVES!$G$7:$G$200,$U25))) -> 2.02 | I25: =IF($U25="","",INDEX(NAVES!$H$7:$H$200,$U25)) -> Parcial | J25: =IF($U25="","",N(INDEX(NAVES!$N$7:$N$200,$U25))) -> 166640 | K25: =IF($U25="","",N(INDEX(NAVES!$I$7:$I$200,$U25))) -> 4792500.4 | L25: =IF($U25="","",N(INDEX(NAVES!$J$7:$J$200,$U25))) -> 8636002.5 | M25: =IF($U25="","",IFERROR(F25/SUMIF(NAVES!$A$7:$A$200,$B$4,NAVES!$E$7:$E$200)*$I$4*$E$4,0)) -> 24253616 | N25: =IF($U25="","",K25+L25+M25) -> 37682118 | O25: =IF($U25="","",IFERROR(N25/$E$4,"")) -> 41637.7 | P25: =IF($U25="","",IFERROR(J25-O25,"")) -> 125002.3 | Q25: =IF($U25="","",IFERROR(P25/J25,"")) -> 0.75013382 | R25: =IF($U25="","",IFERROR(J25/F25,"")) -> 430.59432 | S25: =IF($U25="","",IFERROR(O25/F25,"")) -> 107.59096 | U25: =IFERROR(MATCH(16,NAVES!$P$7:$P$200,0),"") -> 91
A26: =IF($U26="","",17) -> 17 | B26: =IF($U26="","",INDEX(NAVES!$B$7:$B$200,$U26)) -> 8444 | C26: =IF($U26="","",IF(INDEX(NAVES!$M$7:$M$200,$U26)="","",INDEX(NAVES!$M$7:$M$200,$U26))) -> 2026-198 | D26: =IF($U26="","",INDEX(NAVES!$C$7:$C$200,$U26)) -> Por confirmar | E26: =IF($U26="","",INDEX(NAVES!$D$7:$D$200,$U26)) -> ALIOTH 3 | F26: =IF($U26="","",INDEX(NAVES!$E$7:$E$200,$U26)) -> 1 | G26: =IF($U26="","",IF(INDEX(NAVES!$F$7:$F$200,$U26)="","",INDEX(NAVES!$F$7:$F$200,$U26))) -> 1 | H26: =IF($U26="","",IF(INDEX(NAVES!$G$7:$G$200,$U26)="","",INDEX(NAVES!$G$7:$G$200,$U26))) -> 4.01 | I26: =IF($U26="","",INDEX(NAVES!$H$7:$H$200,$U26)) -> Disponible | J26: =IF($U26="","",N(INDEX(NAVES!$N$7:$N$200,$U26))) -> 656 | K26: =IF($U26="","",N(INDEX(NAVES!$I$7:$I$200,$U26))) -> 12383.722 | L26: =IF($U26="","",N(INDEX(NAVES!$J$7:$J$200,$U26))) -> 22315.252 | M26: =IF($U26="","",IFERROR(F26/SUMIF(NAVES!$A$7:$A$200,$B$4,NAVES!$E$7:$E$200)*$I$4*$E$4,0)) -> 62670.841 | N26: =IF($U26="","",K26+L26+M26) -> 97369.815 | O26: =IF($U26="","",IFERROR(N26/$E$4,"")) -> 107.59096 | P26: =IF($U26="","",IFERROR(J26-O26,"")) -> 548.40904 | Q26: =IF($U26="","",IFERROR(P26/J26,"")) -> 0.8359894 | R26: =IF($U26="","",IFERROR(J26/F26,"")) -> 656 | S26: =IF($U26="","",IFERROR(O26/F26,"")) -> 107.59096 | U26: =IFERROR(MATCH(17,NAVES!$P$7:$P$200,0),"") -> 92
A27: =IF($U27="","",18) -> 18 | B27: =IF($U27="","",INDEX(NAVES!$B$7:$B$200,$U27)) -> 8445 | C27: =IF($U27="","",IF(INDEX(NAVES!$M$7:$M$200,$U27)="","",INDEX(NAVES!$M$7:$M$200,$U27))) -> 2026-202 | D27: =IF($U27="","",INDEX(NAVES!$C$7:$C$200,$U27)) -> Por confirmar | E27: =IF($U27="","",INDEX(NAVES!$D$7:$D$200,$U27)) -> CAPE BRUNO 3 | F27: =IF($U27="","",INDEX(NAVES!$E$7:$E$200,$U27)) -> 3 | G27: =IF($U27="","",IF(INDEX(NAVES!$F$7:$F$200,$U27)="","",INDEX(NAVES!$F$7:$F$200,$U27))) -> 1 | H27: =IF($U27="","",IF(INDEX(NAVES!$G$7:$G$200,$U27)="","",INDEX(NAVES!$G$7:$G$200,$U27))) -> 2.42 | I27: =IF($U27="","",INDEX(NAVES!$H$7:$H$200,$U27)) -> Parcial | J27: =IF($U27="","",N(INDEX(NAVES!$N$7:$N$200,$U27))) -> 552 | K27: =IF($U27="","",N(INDEX(NAVES!$I$7:$I$200,$U27))) -> 37151.166 | L27: =IF($U27="","",N(INDEX(NAVES!$J$7:$J$200,$U27))) -> 66945.756 | M27: =IF($U27="","",IFERROR(F27/SUMIF(NAVES!$A$7:$A$200,$B$4,NAVES!$E$7:$E$200)*$I$4*$E$4,0)) -> 188012.52 | N27: =IF($U27="","",K27+L27+M27) -> 292109.44 | O27: =IF($U27="","",IFERROR(N27/$E$4,"")) -> 322.77287 | P27: =IF($U27="","",IFERROR(J27-O27,"")) -> 229.22713 | Q27: =IF($U27="","",IFERROR(P27/J27,"")) -> 0.41526654 | R27: =IF($U27="","",IFERROR(J27/F27,"")) -> 184 | S27: =IF($U27="","",IFERROR(O27/F27,"")) -> 107.59096 | U27: =IFERROR(MATCH(18,NAVES!$P$7:$P$200,0),"") -> 93
A28: =IF($U28="","",19) | B28: =IF($U28="","",INDEX(NAVES!$B$7:$B$200,$U28)) | C28: =IF($U28="","",IF(INDEX(NAVES!$M$7:$M$200,$U28)="","",INDEX(NAVES!$M$7:$M$200,$U28))) | D28: =IF($U28="","",INDEX(NAVES!$C$7:$C$200,$U28)) | E28: =IF($U28="","",INDEX(NAVES!$D$7:$D$200,$U28)) | F28: =IF($U28="","",INDEX(NAVES!$E$7:$E$200,$U28)) | G28: =IF($U28="","",IF(INDEX(NAVES!$F$7:$F$200,$U28)="","",INDEX(NAVES!$F$7:$F$200,$U28))) | H28: =IF($U28="","",IF(INDEX(NAVES!$G$7:$G$200,$U28)="","",INDEX(NAVES!$G$7:$G$200,$U28))) | I28: =IF($U28="","",INDEX(NAVES!$H$7:$H$200,$U28)) | J28: =IF($U28="","",N(INDEX(NAVES!$N$7:$N$200,$U28))) | K28: =IF($U28="","",N(INDEX(NAVES!$I$7:$I$200,$U28))) | L28: =IF($U28="","",N(INDEX(NAVES!$J$7:$J$200,$U28))) | M28: =IF($U28="","",IFERROR(F28/SUMIF(NAVES!$A$7:$A$200,$B$4,NAVES!$E$7:$E$200)*$I$4*$E$4,0)) | N28: =IF($U28="","",K28+L28+M28) | O28: =IF($U28="","",IFERROR(N28/$E$4,"")) | P28: =IF($U28="","",IFERROR(J28-O28,"")) | Q28: =IF($U28="","",IFERROR(P28/J28,"")) | R28: =IF($U28="","",IFERROR(J28/F28,"")) | S28: =IF($U28="","",IFERROR(O28/F28,"")) | U28: =IFERROR(MATCH(19,NAVES!$P$7:$P$200,0),"")
A29: =IF($U29="","",20) | B29: =IF($U29="","",INDEX(NAVES!$B$7:$B$200,$U29)) | C29: =IF($U29="","",IF(INDEX(NAVES!$M$7:$M$200,$U29)="","",INDEX(NAVES!$M$7:$M$200,$U29))) | D29: =IF($U29="","",INDEX(NAVES!$C$7:$C$200,$U29)) | E29: =IF($U29="","",INDEX(NAVES!$D$7:$D$200,$U29)) | F29: =IF($U29="","",INDEX(NAVES!$E$7:$E$200,$U29)) | G29: =IF($U29="","",IF(INDEX(NAVES!$F$7:$F$200,$U29)="","",INDEX(NAVES!$F$7:$F$200,$U29))) | H29: =IF($U29="","",IF(INDEX(NAVES!$G$7:$G$200,$U29)="","",INDEX(NAVES!$G$7:$G$200,$U29))) | I29: =IF($U29="","",INDEX(NAVES!$H$7:$H$200,$U29)) | J29: =IF($U29="","",N(INDEX(NAVES!$N$7:$N$200,$U29))) | K29: =IF($U29="","",N(INDEX(NAVES!$I$7:$I$200,$U29))) | L29: =IF($U29="","",N(INDEX(NAVES!$J$7:$J$200,$U29))) | M29: =IF($U29="","",IFERROR(F29/SUMIF(NAVES!$A$7:$A$200,$B$4,NAVES!$E$7:$E$200)*$I$4*$E$4,0)) | N29: =IF($U29="","",K29+L29+M29) | O29: =IF($U29="","",IFERROR(N29/$E$4,"")) | P29: =IF($U29="","",IFERROR(J29-O29,"")) | Q29: =IF($U29="","",IFERROR(P29/J29,"")) | R29: =IF($U29="","",IFERROR(J29/F29,"")) | S29: =IF($U29="","",IFERROR(O29/F29,"")) | U29: =IFERROR(MATCH(20,NAVES!$P$7:$P$200,0),"")
A30: =IF($U30="","",21) | B30: =IF($U30="","",INDEX(NAVES!$B$7:$B$200,$U30)) | C30: =IF($U30="","",IF(INDEX(NAVES!$M$7:$M$200,$U30)="","",INDEX(NAVES!$M$7:$M$200,$U30))) | D30: =IF($U30="","",INDEX(NAVES!$C$7:$C$200,$U30)) | E30: =IF($U30="","",INDEX(NAVES!$D$7:$D$200,$U30)) | F30: =IF($U30="","",INDEX(NAVES!$E$7:$E$200,$U30)) | G30: =IF($U30="","",IF(INDEX(NAVES!$F$7:$F$200,$U30)="","",INDEX(NAVES!$F$7:$F$200,$U30))) | H30: =IF($U30="","",IF(INDEX(NAVES!$G$7:$G$200,$U30)="","",INDEX(NAVES!$G$7:$G$200,$U30))) | I30: =IF($U30="","",INDEX(NAVES!$H$7:$H$200,$U30)) | J30: =IF($U30="","",N(INDEX(NAVES!$N$7:$N$200,$U30))) | K30: =IF($U30="","",N(INDEX(NAVES!$I$7:$I$200,$U30))) | L30: =IF($U30="","",N(INDEX(NAVES!$J$7:$J$200,$U30))) | M30: =IF($U30="","",IFERROR(F30/SUMIF(NAVES!$A$7:$A$200,$B$4,NAVES!$E$7:$E$200)*$I$4*$E$4,0)) | N30: =IF($U30="","",K30+L30+M30) | O30: =IF($U30="","",IFERROR(N30/$E$4,"")) | P30: =IF($U30="","",IFERROR(J30-O30,"")) | Q30: =IF($U30="","",IFERROR(P30/J30,"")) | R30: =IF($U30="","",IFERROR(J30/F30,"")) | S30: =IF($U30="","",IFERROR(O30/F30,"")) | U30: =IFERROR(MATCH(21,NAVES!$P$7:$P$200,0),"")
A31: =IF($U31="","",22) | B31: =IF($U31="","",INDEX(NAVES!$B$7:$B$200,$U31)) | C31: =IF($U31="","",IF(INDEX(NAVES!$M$7:$M$200,$U31)="","",INDEX(NAVES!$M$7:$M$200,$U31))) | D31: =IF($U31="","",INDEX(NAVES!$C$7:$C$200,$U31)) | E31: =IF($U31="","",INDEX(NAVES!$D$7:$D$200,$U31)) | F31: =IF($U31="","",INDEX(NAVES!$E$7:$E$200,$U31)) | G31: =IF($U31="","",IF(INDEX(NAVES!$F$7:$F$200,$U31)="","",INDEX(NAVES!$F$7:$F$200,$U31))) | H31: =IF($U31="","",IF(INDEX(NAVES!$G$7:$G$200,$U31)="","",INDEX(NAVES!$G$7:$G$200,$U31))) | I31: =IF($U31="","",INDEX(NAVES!$H$7:$H$200,$U31)) | J31: =IF($U31="","",N(INDEX(NAVES!$N$7:$N$200,$U31))) | K31: =IF($U31="","",N(INDEX(NAVES!$I$7:$I$200,$U31))) | L31: =IF($U31="","",N(INDEX(NAVES!$J$7:$J$200,$U31))) | M31: =IF($U31="","",IFERROR(F31/SUMIF(NAVES!$A$7:$A$200,$B$4,NAVES!$E$7:$E$200)*$I$4*$E$4,0)) | N31: =IF($U31="","",K31+L31+M31) | O31: =IF($U31="","",IFERROR(N31/$E$4,"")) | P31: =IF($U31="","",IFERROR(J31-O31,"")) | Q31: =IF($U31="","",IFERROR(P31/J31,"")) | R31: =IF($U31="","",IFERROR(J31/F31,"")) | S31: =IF($U31="","",IFERROR(O31/F31,"")) | U31: =IFERROR(MATCH(22,NAVES!$P$7:$P$200,0),"")
A32: =IF($U32="","",23) | B32: =IF($U32="","",INDEX(NAVES!$B$7:$B$200,$U32)) | C32: =IF($U32="","",IF(INDEX(NAVES!$M$7:$M$200,$U32)="","",INDEX(NAVES!$M$7:$M$200,$U32))) | D32: =IF($U32="","",INDEX(NAVES!$C$7:$C$200,$U32)) | E32: =IF($U32="","",INDEX(NAVES!$D$7:$D$200,$U32)) | F32: =IF($U32="","",INDEX(NAVES!$E$7:$E$200,$U32)) | G32: =IF($U32="","",IF(INDEX(NAVES!$F$7:$F$200,$U32)="","",INDEX(NAVES!$F$7:$F$200,$U32))) | H32: =IF($U32="","",IF(INDEX(NAVES!$G$7:$G$200,$U32)="","",INDEX(NAVES!$G$7:$G$200,$U32))) | I32: =IF($U32="","",INDEX(NAVES!$H$7:$H$200,$U32)) | J32: =IF($U32="","",N(INDEX(NAVES!$N$7:$N$200,$U32))) | K32: =IF($U32="","",N(INDEX(NAVES!$I$7:$I$200,$U32))) | L32: =IF($U32="","",N(INDEX(NAVES!$J$7:$J$200,$U32))) | M32: =IF($U32="","",IFERROR(F32/SUMIF(NAVES!$A$7:$A$200,$B$4,NAVES!$E$7:$E$200)*$I$4*$E$4,0)) | N32: =IF($U32="","",K32+L32+M32) | O32: =IF($U32="","",IFERROR(N32/$E$4,"")) | P32: =IF($U32="","",IFERROR(J32-O32,"")) | Q32: =IF($U32="","",IFERROR(P32/J32,"")) | R32: =IF($U32="","",IFERROR(J32/F32,"")) | S32: =IF($U32="","",IFERROR(O32/F32,"")) | U32: =IFERROR(MATCH(23,NAVES!$P$7:$P$200,0),"")
A33: =IF($U33="","",24) | B33: =IF($U33="","",INDEX(NAVES!$B$7:$B$200,$U33)) | C33: =IF($U33="","",IF(INDEX(NAVES!$M$7:$M$200,$U33)="","",INDEX(NAVES!$M$7:$M$200,$U33))) | D33: =IF($U33="","",INDEX(NAVES!$C$7:$C$200,$U33)) | E33: =IF($U33="","",INDEX(NAVES!$D$7:$D$200,$U33)) | F33: =IF($U33="","",INDEX(NAVES!$E$7:$E$200,$U33)) | G33: =IF($U33="","",IF(INDEX(NAVES!$F$7:$F$200,$U33)="","",INDEX(NAVES!$F$7:$F$200,$U33))) | H33: =IF($U33="","",IF(INDEX(NAVES!$G$7:$G$200,$U33)="","",INDEX(NAVES!$G$7:$G$200,$U33))) | I33: =IF($U33="","",INDEX(NAVES!$H$7:$H$200,$U33)) | J33: =IF($U33="","",N(INDEX(NAVES!$N$7:$N$200,$U33))) | K33: =IF($U33="","",N(INDEX(NAVES!$I$7:$I$200,$U33))) | L33: =IF($U33="","",N(INDEX(NAVES!$J$7:$J$200,$U33))) | M33: =IF($U33="","",IFERROR(F33/SUMIF(NAVES!$A$7:$A$200,$B$4,NAVES!$E$7:$E$200)*$I$4*$E$4,0)) | N33: =IF($U33="","",K33+L33+M33) | O33: =IF($U33="","",IFERROR(N33/$E$4,"")) | P33: =IF($U33="","",IFERROR(J33-O33,"")) | Q33: =IF($U33="","",IFERROR(P33/J33,"")) | R33: =IF($U33="","",IFERROR(J33/F33,"")) | S33: =IF($U33="","",IFERROR(O33/F33,"")) | U33: =IFERROR(MATCH(24,NAVES!$P$7:$P$200,0),"")
A34: =IF($U34="","",25) | B34: =IF($U34="","",INDEX(NAVES!$B$7:$B$200,$U34)) | C34: =IF($U34="","",IF(INDEX(NAVES!$M$7:$M$200,$U34)="","",INDEX(NAVES!$M$7:$M$200,$U34))) | D34: =IF($U34="","",INDEX(NAVES!$C$7:$C$200,$U34)) | E34: =IF($U34="","",INDEX(NAVES!$D$7:$D$200,$U34)) | F34: =IF($U34="","",INDEX(NAVES!$E$7:$E$200,$U34)) | G34: =IF($U34="","",IF(INDEX(NAVES!$F$7:$F$200,$U34)="","",INDEX(NAVES!$F$7:$F$200,$U34))) | H34: =IF($U34="","",IF(INDEX(NAVES!$G$7:$G$200,$U34)="","",INDEX(NAVES!$G$7:$G$200,$U34))) | I34: =IF($U34="","",INDEX(NAVES!$H$7:$H$200,$U34)) | J34: =IF($U34="","",N(INDEX(NAVES!$N$7:$N$200,$U34))) | K34: =IF($U34="","",N(INDEX(NAVES!$I$7:$I$200,$U34))) | L34: =IF($U34="","",N(INDEX(NAVES!$J$7:$J$200,$U34))) | M34: =IF($U34="","",IFERROR(F34/SUMIF(NAVES!$A$7:$A$200,$B$4,NAVES!$E$7:$E$200)*$I$4*$E$4,0)) | N34: =IF($U34="","",K34+L34+M34) | O34: =IF($U34="","",IFERROR(N34/$E$4,"")) | P34: =IF($U34="","",IFERROR(J34-O34,"")) | Q34: =IF($U34="","",IFERROR(P34/J34,"")) | R34: =IF($U34="","",IFERROR(J34/F34,"")) | S34: =IF($U34="","",IFERROR(O34/F34,"")) | U34: =IFERROR(MATCH(25,NAVES!$P$7:$P$200,0),"")
A35: =IF($U35="","",26) | B35: =IF($U35="","",INDEX(NAVES!$B$7:$B$200,$U35)) | C35: =IF($U35="","",IF(INDEX(NAVES!$M$7:$M$200,$U35)="","",INDEX(NAVES!$M$7:$M$200,$U35))) | D35: =IF($U35="","",INDEX(NAVES!$C$7:$C$200,$U35)) | E35: =IF($U35="","",INDEX(NAVES!$D$7:$D$200,$U35)) | F35: =IF($U35="","",INDEX(NAVES!$E$7:$E$200,$U35)) | G35: =IF($U35="","",IF(INDEX(NAVES!$F$7:$F$200,$U35)="","",INDEX(NAVES!$F$7:$F$200,$U35))) | H35: =IF($U35="","",IF(INDEX(NAVES!$G$7:$G$200,$U35)="","",INDEX(NAVES!$G$7:$G$200,$U35))) | I35: =IF($U35="","",INDEX(NAVES!$H$7:$H$200,$U35)) | J35: =IF($U35="","",N(INDEX(NAVES!$N$7:$N$200,$U35))) | K35: =IF($U35="","",N(INDEX(NAVES!$I$7:$I$200,$U35))) | L35: =IF($U35="","",N(INDEX(NAVES!$J$7:$J$200,$U35))) | M35: =IF($U35="","",IFERROR(F35/SUMIF(NAVES!$A$7:$A$200,$B$4,NAVES!$E$7:$E$200)*$I$4*$E$4,0)) | N35: =IF($U35="","",K35+L35+M35) | O35: =IF($U35="","",IFERROR(N35/$E$4,"")) | P35: =IF($U35="","",IFERROR(J35-O35,"")) | Q35: =IF($U35="","",IFERROR(P35/J35,"")) | R35: =IF($U35="","",IFERROR(J35/F35,"")) | S35: =IF($U35="","",IFERROR(O35/F35,"")) | U35: =IFERROR(MATCH(26,NAVES!$P$7:$P$200,0),"")
A36: =IF($U36="","",27) | B36: =IF($U36="","",INDEX(NAVES!$B$7:$B$200,$U36)) | C36: =IF($U36="","",IF(INDEX(NAVES!$M$7:$M$200,$U36)="","",INDEX(NAVES!$M$7:$M$200,$U36))) | D36: =IF($U36="","",INDEX(NAVES!$C$7:$C$200,$U36)) | E36: =IF($U36="","",INDEX(NAVES!$D$7:$D$200,$U36)) | F36: =IF($U36="","",INDEX(NAVES!$E$7:$E$200,$U36)) | G36: =IF($U36="","",IF(INDEX(NAVES!$F$7:$F$200,$U36)="","",INDEX(NAVES!$F$7:$F$200,$U36))) | H36: =IF($U36="","",IF(INDEX(NAVES!$G$7:$G$200,$U36)="","",INDEX(NAVES!$G$7:$G$200,$U36))) | I36: =IF($U36="","",INDEX(NAVES!$H$7:$H$200,$U36)) | J36: =IF($U36="","",N(INDEX(NAVES!$N$7:$N$200,$U36))) | K36: =IF($U36="","",N(INDEX(NAVES!$I$7:$I$200,$U36))) | L36: =IF($U36="","",N(INDEX(NAVES!$J$7:$J$200,$U36))) | M36: =IF($U36="","",IFERROR(F36/SUMIF(NAVES!$A$7:$A$200,$B$4,NAVES!$E$7:$E$200)*$I$4*$E$4,0)) | N36: =IF($U36="","",K36+L36+M36) | O36: =IF($U36="","",IFERROR(N36/$E$4,"")) | P36: =IF($U36="","",IFERROR(J36-O36,"")) | Q36: =IF($U36="","",IFERROR(P36/J36,"")) | R36: =IF($U36="","",IFERROR(J36/F36,"")) | S36: =IF($U36="","",IFERROR(O36/F36,"")) | U36: =IFERROR(MATCH(27,NAVES!$P$7:$P$200,0),"")
A37: =IF($U37="","",28) | B37: =IF($U37="","",INDEX(NAVES!$B$7:$B$200,$U37)) | C37: =IF($U37="","",IF(INDEX(NAVES!$M$7:$M$200,$U37)="","",INDEX(NAVES!$M$7:$M$200,$U37))) | D37: =IF($U37="","",INDEX(NAVES!$C$7:$C$200,$U37)) | E37: =IF($U37="","",INDEX(NAVES!$D$7:$D$200,$U37)) | F37: =IF($U37="","",INDEX(NAVES!$E$7:$E$200,$U37)) | G37: =IF($U37="","",IF(INDEX(NAVES!$F$7:$F$200,$U37)="","",INDEX(NAVES!$F$7:$F$200,$U37))) | H37: =IF($U37="","",IF(INDEX(NAVES!$G$7:$G$200,$U37)="","",INDEX(NAVES!$G$7:$G$200,$U37))) | I37: =IF($U37="","",INDEX(NAVES!$H$7:$H$200,$U37)) | J37: =IF($U37="","",N(INDEX(NAVES!$N$7:$N$200,$U37))) | K37: =IF($U37="","",N(INDEX(NAVES!$I$7:$I$200,$U37))) | L37: =IF($U37="","",N(INDEX(NAVES!$J$7:$J$200,$U37))) | M37: =IF($U37="","",IFERROR(F37/SUMIF(NAVES!$A$7:$A$200,$B$4,NAVES!$E$7:$E$200)*$I$4*$E$4,0)) | N37: =IF($U37="","",K37+L37+M37) | O37: =IF($U37="","",IFERROR(N37/$E$4,"")) | P37: =IF($U37="","",IFERROR(J37-O37,"")) | Q37: =IF($U37="","",IFERROR(P37/J37,"")) | R37: =IF($U37="","",IFERROR(J37/F37,"")) | S37: =IF($U37="","",IFERROR(O37/F37,"")) | U37: =IFERROR(MATCH(28,NAVES!$P$7:$P$200,0),"")
A38: =IF($U38="","",29) | B38: =IF($U38="","",INDEX(NAVES!$B$7:$B$200,$U38)) | C38: =IF($U38="","",IF(INDEX(NAVES!$M$7:$M$200,$U38)="","",INDEX(NAVES!$M$7:$M$200,$U38))) | D38: =IF($U38="","",INDEX(NAVES!$C$7:$C$200,$U38)) | E38: =IF($U38="","",INDEX(NAVES!$D$7:$D$200,$U38)) | F38: =IF($U38="","",INDEX(NAVES!$E$7:$E$200,$U38)) | G38: =IF($U38="","",IF(INDEX(NAVES!$F$7:$F$200,$U38)="","",INDEX(NAVES!$F$7:$F$200,$U38))) | H38: =IF($U38="","",IF(INDEX(NAVES!$G$7:$G$200,$U38)="","",INDEX(NAVES!$G$7:$G$200,$U38))) | I38: =IF($U38="","",INDEX(NAVES!$H$7:$H$200,$U38)) | J38: =IF($U38="","",N(INDEX(NAVES!$N$7:$N$200,$U38))) | K38: =IF($U38="","",N(INDEX(NAVES!$I$7:$I$200,$U38))) | L38: =IF($U38="","",N(INDEX(NAVES!$J$7:$J$200,$U38))) | M38: =IF($U38="","",IFERROR(F38/SUMIF(NAVES!$A$7:$A$200,$B$4,NAVES!$E$7:$E$200)*$I$4*$E$4,0)) | N38: =IF($U38="","",K38+L38+M38) | O38: =IF($U38="","",IFERROR(N38/$E$4,"")) | P38: =IF($U38="","",IFERROR(J38-O38,"")) | Q38: =IF($U38="","",IFERROR(P38/J38,"")) | R38: =IF($U38="","",IFERROR(J38/F38,"")) | S38: =IF($U38="","",IFERROR(O38/F38,"")) | U38: =IFERROR(MATCH(29,NAVES!$P$7:$P$200,0),"")
A39: =IF($U39="","",30) | B39: =IF($U39="","",INDEX(NAVES!$B$7:$B$200,$U39)) | C39: =IF($U39="","",IF(INDEX(NAVES!$M$7:$M$200,$U39)="","",INDEX(NAVES!$M$7:$M$200,$U39))) | D39: =IF($U39="","",INDEX(NAVES!$C$7:$C$200,$U39)) | E39: =IF($U39="","",INDEX(NAVES!$D$7:$D$200,$U39)) | F39: =IF($U39="","",INDEX(NAVES!$E$7:$E$200,$U39)) | G39: =IF($U39="","",IF(INDEX(NAVES!$F$7:$F$200,$U39)="","",INDEX(NAVES!$F$7:$F$200,$U39))) | H39: =IF($U39="","",IF(INDEX(NAVES!$G$7:$G$200,$U39)="","",INDEX(NAVES!$G$7:$G$200,$U39))) | I39: =IF($U39="","",INDEX(NAVES!$H$7:$H$200,$U39)) | J39: =IF($U39="","",N(INDEX(NAVES!$N$7:$N$200,$U39))) | K39: =IF($U39="","",N(INDEX(NAVES!$I$7:$I$200,$U39))) | L39: =IF($U39="","",N(INDEX(NAVES!$J$7:$J$200,$U39))) | M39: =IF($U39="","",IFERROR(F39/SUMIF(NAVES!$A$7:$A$200,$B$4,NAVES!$E$7:$E$200)*$I$4*$E$4,0)) | N39: =IF($U39="","",K39+L39+M39) | O39: =IF($U39="","",IFERROR(N39/$E$4,"")) | P39: =IF($U39="","",IFERROR(J39-O39,"")) | Q39: =IF($U39="","",IFERROR(P39/J39,"")) | R39: =IF($U39="","",IFERROR(J39/F39,"")) | S39: =IF($U39="","",IFERROR(O39/F39,"")) | U39: =IFERROR(MATCH(30,NAVES!$P$7:$P$200,0),"")
A40: TOTAL MES | F40: =SUM(F10:F39) -> 1151 | G40: =SUM(G10:G39) -> 1145 | H40: =IFERROR(SUMPRODUCT((NAVES!$A$7:$A$200=$B$4)*NAVES!$F$7:$F$200*NAVES!$G$7:$G$200)/SUMIF(NAVES!$A$7:$A$200,$B$4,NAVES!$F$7:$F$200),"") -> 2.8327074 | J40: =SUM(J10:J39) -> 630824 | K40: =SUM(K10:K39) -> 14253664 | L40: =SUM(L10:L39) -> 25684855 | M40: =SUM(M10:M39) -> 72134138 | N40: =SUM(N10:N39) -> 1.1207266e+08 | O40: =SUM(O10:O39) -> 123837.19 | P40: =SUM(P10:P39) -> 506986.81 | Q40: =IFERROR(P40/J40,"") -> 0.80368979 | R40: =IFERROR(J40/F40,"") -> 548.06603 | S40: =IFERROR(O40/F40,"") -> 107.59096
A42: Notas: venta por nave según "Servicio Reefer" de Naves por Servicios (cuadra con RESUMEN; ver control en P4). Naves sin venta (descargas, EDP pendiente) muestran margen negativo por el costo asignado. Columna U: auxiliar.
A44: ="VENTA vs COSTO POR NAVE — "&UPPER($B$4)&" 2026" -> VENTA vs COSTO POR NAVE — SEPTIEMBRE 2026

Sheet CONEXIONES
A1: CONEXIONES SIMULTÁNEAS REEFER 2026 — POR DÍA Y POR MES
A2: Elige el mes en la celda amarilla. Máx. simultáneo = mayor cantidad de reefers conectados al mismo tiempo en el día (al minuto), según el detalle de los EDP (pestaña DATOS_CONEX). PPK = equipos arrendados ese día según pestaña PPK.
A4: MES | B4: Septiembre | E4: Umbral peak | F4: 200 | H4: EDP del mes | I4: =IF(COUNTIF(DATOS_CONEX!$B$7:$B$4000,$B$4)=0,"Falta EDP","Cargado ("&COUNTIFS(DATOS_CONEX!$B$7:$B$4000,$B$4,DATOS_CONEX!$I$7:$I$4000,"Sí")&" válidos)") -> Cargado (1146 válidos) | M4: Excluidos del EDP | O4: =COUNTIFS(DATOS_CONEX!$B$7:$B$4000,$B$4,DATOS_CONEX!$I$7:$I$4000,"No") -> 8 | Z4: =MATCH($B$4,{"Enero","Febrero","Marzo","Abril","Mayo","Junio","Julio","Agosto","Septiembre","Octubre","Noviembre","Diciembre"},0) -> 9
A6: MÁX. SIMULTÁNEO | C6: FECHA / HORA DEL MÁX. | E6: NAVE AL MÁX. | G6: PROMEDIO EN PARALELO | I6: DÍAS ≥ UMBRAL | K6: MÁX. PPK EN UN DÍA | M6: PROM. MÁX. DIARIO | O6: REEFER-DÍAS DEL MES
A7: =IFERROR(MAX(D10:D40),"") -> 400 | C7: =IFERROR(IFERROR(INDEX(DATOS_CONEX!$F$7:$F$4000,MATCH($B$4&"|"&A7,DATOS_CONEX!$N$7:$N$4000,0)),"Inicio de mes"),"") -> 46290.938 | E7: =IFERROR(IFERROR(INDEX(DATOS_CONEX!$C$7:$C$4000,MATCH($B$4&"|"&A7,DATOS_CONEX!$N$7:$N$4000,0)),"-"),"") -> POLAR COLOMBIA | G7: =IFERROR(SUMPRODUCT((DATOS_CONEX!$I$7:$I$4000="Sí")*(((DATOS_CONEX!$G$7:$G$4000+DATE(2026,$Z$4+1,1)-ABS(DATOS_CONEX!$G$7:$G$4000-DATE(2026,$Z$4+1,1)))/2-(DATOS_CONEX!$F$7:$F$4000+DATE(2026,$Z$4,1)+ABS(DATOS_CONEX!$F$7:$F$4000-DATE(2026,$Z$4,1)))/2)+ABS(((DATOS_CONEX!$G$7:$G$4000+DATE(2026,$Z$4+1,1)-ABS(DATOS_CONEX!$G$7:$G$4000-DATE(2026,$Z$4+1,1)))/2-(DATOS_CONEX!$F$7:$F$4000+DATE(2026,$Z$4,1)+ABS(DATOS_CONEX!$F$7:$F$4000-DATE(2026,$Z$4,1)))/2)))/2)/(DATE(2026,$Z$4+1,1)-DATE(2026,$Z$4,1)),"") -> 105.59009 | I7: =IFERROR(COUNTIF(D10:D40,">="&$F$4),"") -> 10 | K7: =IFERROR(MAX(G10:G40),"") -> 8 | M7: =IFERROR(IFERROR(AVERAGE(D10:D40),""),"") -> 137.56667 | O7: =IFERROR(I41,"") -> 3167.7028
A9: Fecha | B9: Día | C9: Conectados 00:00 | D9: Máx. simultáneo | E9: Conexiones | F9: Desconexiones | G9: PPK arrendados | H9: Reefers conectados en el día | I9: Reefer-días (equiv. 24 h)
